2024-05-31 21:27:33,864 INFO    StreamThr :30395 [internal.py:wandb_internal():85] W&B internal server running at pid: 30395, started at: 2024-05-31 21:27:33.862746
2024-05-31 21:27:33,867 DEBUG   HandlerThread:30395 [handler.py:handle_request():158] handle_request: status
2024-05-31 21:27:33,869 INFO    WriterThread:30395 [datastore.py:open_for_write():87] open: /cephfs/zhanjh/COMP130207/PJ2/wandb/run-20240531_212733-gxd0t07e/run-gxd0t07e.wandb
2024-05-31 21:27:33,874 DEBUG   SenderThread:30395 [sender.py:send():378] send: header
2024-05-31 21:27:33,888 DEBUG   SenderThread:30395 [sender.py:send():378] send: run
2024-05-31 21:27:34,967 ERROR   SenderThread:30395 [internal_api.py:execute():344] 404 response executing GraphQL.
2024-05-31 21:27:34,967 ERROR   SenderThread:30395 [internal_api.py:execute():345] {"errors":[{"message":"entity Zhan Jiahao not found during upsertBucket","path":["upsertBucket"]}],"data":{"upsertBucket":null}}
2024-05-31 21:27:34,968 ERROR   SenderThread:30395 [sender.py:send_run():970] It appears that you do not have permission to access the requested resource. Please reach out to the project owner to grant you access. If you have the correct permissions, verify that there are no issues with your networking setup.(Error 404: Not Found)
Traceback (most recent call last):
  File "/root/miniconda3/envs/ai/lib/python3.8/site-packages/wandb/sdk/lib/retry.py", line 131, in __call__
    result = self._call_fn(*args, **kwargs)
  File "/root/miniconda3/envs/ai/lib/python3.8/site-packages/wandb/sdk/internal/internal_api.py", line 340, in execute
    return self.client.execute(*args, **kwargs)  # type: ignore
  File "/root/miniconda3/envs/ai/lib/python3.8/site-packages/wandb/vendor/gql-0.2.0/wandb_gql/client.py", line 52, in execute
    result = self._get_result(document, *args, **kwargs)
  File "/root/miniconda3/envs/ai/lib/python3.8/site-packages/wandb/vendor/gql-0.2.0/wandb_gql/client.py", line 60, in _get_result
    return self.transport.execute(document, *args, **kwargs)
  File "/root/miniconda3/envs/ai/lib/python3.8/site-packages/wandb/sdk/lib/gql_request.py", line 59, in execute
    request.raise_for_status()
  File "/root/miniconda3/envs/ai/lib/python3.8/site-packages/requests/models.py", line 1024, in raise_for_status
    raise HTTPError(http_error_msg, response=self)
requests.exceptions.HTTPError: 404 Client Error: Not Found for url: https://api.wandb.ai/graphql

During handling of the above exception, another exception occurred:

Traceback (most recent call last):
  File "/root/miniconda3/envs/ai/lib/python3.8/site-packages/wandb/sdk/internal/sender.py", line 968, in send_run
    server_run = self._init_run(run, config_value_dict)
  File "/root/miniconda3/envs/ai/lib/python3.8/site-packages/wandb/sdk/internal/sender.py", line 1013, in _init_run
    server_run, inserted, server_messages = self._api.upsert_run(
  File "/root/miniconda3/envs/ai/lib/python3.8/site-packages/wandb/apis/normalize.py", line 73, in wrapper
    raise err
  File "/root/miniconda3/envs/ai/lib/python3.8/site-packages/wandb/apis/normalize.py", line 41, in wrapper
    return func(*args, **kwargs)
  File "/root/miniconda3/envs/ai/lib/python3.8/site-packages/wandb/sdk/internal/internal_api.py", line 2188, in upsert_run
    response = self.gql(
  File "/root/miniconda3/envs/ai/lib/python3.8/site-packages/wandb/sdk/internal/internal_api.py", line 312, in gql
    ret = self._retry_gql(
  File "/root/miniconda3/envs/ai/lib/python3.8/site-packages/wandb/sdk/lib/retry.py", line 147, in __call__
    retry_timedelta_triggered = check_retry_fn(e)
  File "/root/miniconda3/envs/ai/lib/python3.8/site-packages/wandb/util.py", line 965, in check_retry_fn
    return fallback_retry_fn(e)
  File "/root/miniconda3/envs/ai/lib/python3.8/site-packages/wandb/util.py", line 907, in no_retry_auth
    raise CommError(
wandb.errors.CommError: It appears that you do not have permission to access the requested resource. Please reach out to the project owner to grant you access. If you have the correct permissions, verify that there are no issues with your networking setup.(Error 404: Not Found)
2024-05-31 21:27:35,788 DEBUG   HandlerThread:30395 [handler.py:handle_request():158] handle_request: shutdown
2024-05-31 21:27:35,788 INFO    HandlerThread:30395 [handler.py:finish():882] shutting down handler
2024-05-31 21:27:35,888 INFO    WriterThread:30395 [datastore.py:close():296] close: /cephfs/zhanjh/COMP130207/PJ2/wandb/run-20240531_212733-gxd0t07e/run-gxd0t07e.wandb
2024-05-31 21:27:35,973 INFO    SenderThread:30395 [sender.py:finish():1545] shutting down sender
